Workbook

Sheet Overview
A1: Coinzy Web — Project Timeline
A2: Project start date | B2: 46300
A3: Planning basis | B3: Parallel AI agents; screen tasks use screens/day; leftovers + QA bug backlog use hours. Bug ETA from docs/bug-tracker.html velocity.
A4: Remaining agent workdays | B4: =SUM('Detailed Timeline'!D2:D29)
A5: Calendar weeks | B5: =IF(B6="","",ROUNDUP(NETWORKDAYS(B2,B6)/5,0))
A6: Projected finish | B6: =MAX('Detailed Timeline'!F2:F29)
A7: Overall progress | B7: =IFERROR(SUMPRODUCT('Detailed Timeline'!O2:O29,'Detailed Timeline'!G2:G29)/SUM('Detailed Timeline'!O2:O29),0)
A8: Unscheduled tasks | B8: =COUNTIFS('Detailed Timeline'!L2:L29,"",'Detailed Timeline'!G2:G29,"<1")
A9: Screens per agent per day | B9: 2
A10: Planned screens | B10: =SUM('Detailed Timeline'!L2:L29) | C10: Agent weeks | D10: Progress | E10: Start | F10: Finish
A11: Landing pages | B11: =SUMIF('Detailed Timeline'!B$2:B$29,A11,'Detailed Timeline'!D$2:D$29) | C11: =B11/5 | D11: =IFERROR(SUMPRODUCT(('Detailed Timeline'!B$2:B$29=A11)*'Detailed Timeline'!O$2:O$24*'Detailed Timeline'!G$2:G$24)/SUMIF('Detailed Timeline'!B$2:B$29,A11,'Detailed Timeline'!O$2:O$24),0) | E11: =IF(COUNT('Detailed Timeline'!E2,'Detailed Timeline'!E3)=0,"",MIN('Detailed Timeline'!E2,'Detailed Timeline'!E3)) | F11: =IF(COUNT('Detailed Timeline'!F2,'Detailed Timeline'!F3)=0,"",MAX('Detailed Timeline'!F2,'Detailed Timeline'!F3))
A12: Auth and login | B12: =SUMIF('Detailed Timeline'!B$2:B$29,A12,'Detailed Timeline'!D$2:D$29) | C12: =B12/5 | D12: =IFERROR(SUMPRODUCT(('Detailed Timeline'!B$2:B$29=A12)*'Detailed Timeline'!O$2:O$24*'Detailed Timeline'!G$2:G$24)/SUMIF('Detailed Timeline'!B$2:B$29,A12,'Detailed Timeline'!O$2:O$24),0) | E12: =IF(COUNT('Detailed Timeline'!E4)=0,"",MIN('Detailed Timeline'!E4)) | F12: =IF(COUNT('Detailed Timeline'!F4)=0,"",MAX('Detailed Timeline'!F4))
A13: Homepage | B13: =SUMIF('Detailed Timeline'!B$2:B$29,A13,'Detailed Timeline'!D$2:D$29) | C13: =B13/5 | D13: =IFERROR(SUMPRODUCT(('Detailed Timeline'!B$2:B$29=A13)*'Detailed Timeline'!O$2:O$24*'Detailed Timeline'!G$2:G$24)/SUMIF('Detailed Timeline'!B$2:B$29,A13,'Detailed Timeline'!O$2:O$24),0) | E13: =IF(COUNT('Detailed Timeline'!E5,'Detailed Timeline'!E6)=0,"",MIN('Detailed Timeline'!E5,'Detailed Timeline'!E6)) | F13: =IF(COUNT('Detailed Timeline'!F5,'Detailed Timeline'!F6)=0,"",MAX('Detailed Timeline'!F5,'Detailed Timeline'!F6))
A14: AI Identification | B14: =SUMIF('Detailed Timeline'!B$2:B$29,A14,'Detailed Timeline'!D$2:D$29) | C14: =B14/5 | D14: =IFERROR(SUMPRODUCT(('Detailed Timeline'!B$2:B$29=A14)*'Detailed Timeline'!O$2:O$24*'Detailed Timeline'!G$2:G$24)/SUMIF('Detailed Timeline'!B$2:B$29,A14,'Detailed Timeline'!O$2:O$24),0) | E14: =IF(COUNT('Detailed Timeline'!E7,'Detailed Timeline'!E8)=0,"",MIN('Detailed Timeline'!E7,'Detailed Timeline'!E8)) | F14: =IF(COUNT('Detailed Timeline'!F7,'Detailed Timeline'!F8)=0,"",MAX('Detailed Timeline'!F7,'Detailed Timeline'!F8))
A15: Expert evaluation | B15: =SUMIF('Detailed Timeline'!B$2:B$29,A15,'Detailed Timeline'!D$2:D$29) | C15: =B15/5 | D15: =IFERROR(SUMPRODUCT(('Detailed Timeline'!B$2:B$29=A15)*'Detailed Timeline'!O$2:O$24*'Detailed Timeline'!G$2:G$24)/SUMIF('Detailed Timeline'!B$2:B$29,A15,'Detailed Timeline'!O$2:O$24),0) | E15: =IF(COUNT('Detailed Timeline'!E9,'Detailed Timeline'!E10)=0,"",MIN('Detailed Timeline'!E9,'Detailed Timeline'!E10)) | F15: =IF(COUNT('Detailed Timeline'!F9,'Detailed Timeline'!F10)=0,"",MAX('Detailed Timeline'!F9,'Detailed Timeline'!F10))
A16: Global Catalogue | B16: =SUMIF('Detailed Timeline'!B$2:B$29,A16,'Detailed Timeline'!D$2:D$29) | C16: =B16/5 | D16: =IFERROR(SUMPRODUCT(('Detailed Timeline'!B$2:B$29=A16)*'Detailed Timeline'!O$2:O$24*'Detailed Timeline'!G$2:G$24)/SUMIF('Detailed Timeline'!B$2:B$29,A16,'Detailed Timeline'!O$2:O$24),0) | E16: =IF(COUNT('Detailed Timeline'!E11,'Detailed Timeline'!E12)=0,"",MIN('Detailed Timeline'!E11,'Detailed Timeline'!E12)) | F16: =IF(COUNT('Detailed Timeline'!F11,'Detailed Timeline'!F12)=0,"",MAX('Detailed Timeline'!F11,'Detailed Timeline'!F12))
A17: Marketplace | B17: =SUMIF('Detailed Timeline'!B$2:B$29,A17,'Detailed Timeline'!D$2:D$29) | C17: =B17/5 | D17: =IFERROR(SUMPRODUCT(('Detailed Timeline'!B$2:B$29=A17)*'Detailed Timeline'!O$2:O$24*'Detailed Timeline'!G$2:G$24)/SUMIF('Detailed Timeline'!B$2:B$29,A17,'Detailed Timeline'!O$2:O$24),0) | E17: =IF(COUNT('Detailed Timeline'!E13,'Detailed Timeline'!E14,'Detailed Timeline'!E15)=0,"",MIN('Detailed Timeline'!E13,'Detailed Timeline'!E14,'Detailed Timeline'!E15)) | F17: =IF(COUNT('Detailed Timeline'!F13,'Detailed Timeline'!F14,'Detailed Timeline'!F15)=0,"",MAX('Detailed Timeline'!F13,'Detailed Timeline'!F14,'Detailed Timeline'!F15))
A18: Collections | B18: =SUMIF('Detailed Timeline'!B$2:B$29,A18,'Detailed Timeline'!D$2:D$29) | C18: =B18/5 | D18: =IFERROR(SUMPRODUCT(('Detailed Timeline'!B$2:B$29=A18)*'Detailed Timeline'!O$2:O$24*'Detailed Timeline'!G$2:G$24)/SUMIF('Detailed Timeline'!B$2:B$29,A18,'Detailed Timeline'!O$2:O$24),0) | E18: =IF(COUNT('Detailed Timeline'!E16,'Detailed Timeline'!E17)=0,"",MIN('Detailed Timeline'!E16,'Detailed Timeline'!E17)) | F18: =IF(COUNT('Detailed Timeline'!F16,'Detailed Timeline'!F17)=0,"",MAX('Detailed Timeline'!F16,'Detailed Timeline'!F17))
A19: Feed | B19: =SUMIF('Detailed Timeline'!B$2:B$29,A19,'Detailed Timeline'!D$2:D$29) | C19: =B19/5 | D19: =IFERROR(SUMPRODUCT(('Detailed Timeline'!B$2:B$29=A19)*'Detailed Timeline'!O$2:O$24*'Detailed Timeline'!G$2:G$24)/SUMIF('Detailed Timeline'!B$2:B$29,A19,'Detailed Timeline'!O$2:O$24),0) | E19: =IF(COUNT('Detailed Timeline'!E18,'Detailed Timeline'!E19)=0,"",MIN('Detailed Timeline'!E18,'Detailed Timeline'!E19)) | F19: =IF(COUNT('Detailed Timeline'!F18,'Detailed Timeline'!F19)=0,"",MAX('Detailed Timeline'!F18,'Detailed Timeline'!F19))
A20: Settings | B20: =SUMIF('Detailed Timeline'!B$2:B$29,A20,'Detailed Timeline'!D$2:D$29) | C20: =B20/5 | D20: =IFERROR(SUMPRODUCT(('Detailed Timeline'!B$2:B$29=A20)*'Detailed Timeline'!O$2:O$24*'Detailed Timeline'!G$2:G$24)/SUMIF('Detailed Timeline'!B$2:B$29,A20,'Detailed Timeline'!O$2:O$24),0) | E20: =IF(COUNT('Detailed Timeline'!E20)=0,"",MIN('Detailed Timeline'!E20)) | F20: =IF(COUNT('Detailed Timeline'!F20)=0,"",MAX('Detailed Timeline'!F20))
A21: Payments (deferred) | B21: =SUMIF('Detailed Timeline'!B$2:B$29,A21,'Detailed Timeline'!D$2:D$29) | C21: =B21/5 | D21: =IFERROR(SUMPRODUCT(('Detailed Timeline'!B$2:B$29=A21)*'Detailed Timeline'!O$2:O$24*'Detailed Timeline'!G$2:G$24)/SUMIF('Detailed Timeline'!B$2:B$29,A21,'Detailed Timeline'!O$2:O$24),0) | E21: =IF(COUNT('Detailed Timeline'!E21,'Detailed Timeline'!E22)=0,"",MIN('Detailed Timeline'!E21,'Detailed Timeline'!E22)) | F21: =IF(COUNT('Detailed Timeline'!F21,'Detailed Timeline'!F22)=0,"",MAX('Detailed Timeline'!F21,'Detailed Timeline'!F22))
A22: Review and fixes | B22: =SUMIF('Detailed Timeline'!B$2:B$29,A22,'Detailed Timeline'!D$2:D$29) | C22: =B22/5 | D22: =IFERROR(SUMPRODUCT(('Detailed Timeline'!B$2:B$29=A22)*'Detailed Timeline'!O$2:O$24*'Detailed Timeline'!G$2:G$24)/SUMIF('Detailed Timeline'!B$2:B$29,A22,'Detailed Timeline'!O$2:O$24),0) | E22: =IF(COUNT('Detailed Timeline'!E23)=0,"",MIN('Detailed Timeline'!E23)) | F22: =IF(COUNT('Detailed Timeline'!F23)=0,"",MAX('Detailed Timeline'!F23))
A23: Blogs | B23: =SUMIF('Detailed Timeline'!B$2:B$29,A23,'Detailed Timeline'!D$2:D$29) | C23: =B23/5 | D23: =IFERROR(SUMPRODUCT(('Detailed Timeline'!B$2:B$29=A23)*'Detailed Timeline'!O$2:O$24*'Detailed Timeline'!G$2:G$24)/SUMIF('Detailed Timeline'!B$2:B$29,A23,'Detailed Timeline'!O$2:O$24),0) | E23: =IF(COUNT('Detailed Timeline'!E24)=0,"",MIN('Detailed Timeline'!E24)) | F23: =IF(COUNT('Detailed Timeline'!F24)=0,"",MAX('Detailed Timeline'!F24))
A24: Note | B24: Sync 23 (28 Oct 2026): Critical path = ClickUp web bugs. Velocity 34 pts/day (13 fixed today). 63 open (147 pts) → calendar ETA 2026-11-02 (~5d); workday finish ~2026-11-04. Task 22 = E2E+bug backlog 40h. Deferred (not QA blockers): Payments 20; Premium JWT on task 5.
A25: Note | B25: Bug ETA assumes today’s burst holds. Half-pace (~17 pts/day) → ~2026-11-06. See docs/bug-tracker.html.
A26: Agent lanes | B26: 5
A27: Forecast from (edit) | B27: 46323
A28: Completion dates | B28: Set progress to 100% and record the actual finish in Detailed Timeline column N. Early finishes release dependent work; forecasts use only remaining work and agent availability.
A29: Sort order | B29: Detailed Timeline stays in task-ID order (dependency and agent-lane formulas read earlier rows by position, so sorting it would break the schedule). Weekly View is listed by progress (highest first), then task ID, matching the HTML timeline.
A30: Leftover hours (sum) | B30: =SUMIF('Detailed Timeline'!B$2:B$29,"Leftovers (hours)",'Detailed Timeline'!Q$2:Q$29)
A31: Hours per agent day | B31: 8
A32: Leftovers (hours) | B32: =SUMIF('Detailed Timeline'!B$2:B$29,A32,'Detailed Timeline'!D$2:D$29)

Sheet Detailed Timeline
A1: ID | B1: Section | C1: Work package / deliverable | D1: Remaining workdays | E1: Start date | F1: Finish date | G1: Progress (edit) | H1: Status | I1: Start week | J1: Finish week | K1: Depends on ID (edit) | L1: Screens (edit) | M1: Agent lane | N1: Recorded completion (edit) | O1: Original workdays | P1: Agent busy through | Q1: Hours (edit)
A2: 1 | B2: Landing pages | C2: Main landing page: Main page, shared header/footer and navigation; done with real coin images and favicon | D2: =IF(G2>=1,0,IF(O2="","",ROUNDUP(O2*(1-G2),0))) | E2: =IF(G2>=1,IF(N2="",Overview!$B$27,N2),IF(D2="","",IF(IF(K2=0,FALSE(),INDEX(F$2:F$29,K2)=""),"",WORKDAY(MAX(Overview!$B$2-1,Overview!$B$27-1,IF(K2=0,0,INDEX(F$2:F$29,K2)),0),1)))) | F2: =IF(G2>=1,E2,IF(E2="","",WORKDAY(E2,D2-1))) | G2: 1 | H2: =IF(G2>=1,"Done",IF(O2="","Scope pending",IF(E2="","Waiting on dependency",IF(G2>0,"In progress","Planned")))) | I2: =IF(E2="","",INT((E2-Overview!$B$2)/7)+1) | J2: =IF(F2="","",INT((F2-Overview!$B$2)/7)+1) | K2: 0 | L2: 2 | M2: A | N2: 46300 | O2: =IF(AND(Q2<>"",Q2>0),ROUNDUP(Q2/Overview!$B$31,0),IF(OR(L2="",L2<=0,Overview!$B$9<=0),"",ROUNDUP(L2/Overview!$B$9,0))) | P2: =MAX(0,IF(G2>=1,0,IF(F2="",0,F2)))
A3: 2 | B3: Landing pages | C3: Feature landing pages: Done. Expert CTAs peeled → leftover task 24 (1h). | D3: =IF(G3>=1,0,IF(O3="","",ROUNDUP(O3*(1-G3),0))) | E3: =IF(G3>=1,IF(N3="",Overview!$B$27,N3),IF(D3="","",IF(IF(K3=0,FALSE(),INDEX(F$2:F$29,K3)=""),"",WORKDAY(MAX(Overview!$B$2-1,Overview!$B$27-1,IF(K3=0,0,INDEX(F$2:F$29,K3)),IFERROR(LOOKUP(2,1/(M$2:M2=M3),P$2:P2),0)),1)))) | F3: =IF(G3>=1,E3,IF(E3="","",WORKDAY(E3,D3-1))) | G3: 1 | H3: =IF(G3>=1,"Done",IF(O3="","Scope pending",IF(E3="","Waiting on dependency",IF(G3>0,"In progress","Planned")))) | I3: =IF(E3="","",INT((E3-Overview!$B$2)/7)+1) | J3: =IF(F3="","",INT((F3-Overview!$B$2)/7)+1) | K3: 1 | L3: 6 | M3: A | N3: 46304 | O3: =IF(AND(Q3<>"",Q3>0),ROUNDUP(Q3/Overview!$B$31,0),IF(OR(L3="",L3<=0,Overview!$B$9<=0),"",ROUNDUP(L3/Overview!$B$9,0))) | P3: =MAX(IFERROR(LOOKUP(2,1/(M$2:M2=M3),P$2:P2),0),IF(G3>=1,0,IF(F3="",0,F3)))
A4: 3 | B4: Auth and login | C4: Account access: Done: welcome, email signup/login, guest sessions, forgot/reset APIs, OTP and new-password flow, Figma error states (1758:124172), Trackzio Terms/Privacy links, HTTP-only cookies, signed-in redirects and single-history auth steps; logged-out CTAs use /auth?next= (908/905 auth modals out of scope); Google sign-in disabled on web | D4: =IF(G4>=1,0,IF(O4="","",ROUNDUP(O4*(1-G4),0))) | E4: =IF(G4>=1,IF(N4="",Overview!$B$27,N4),IF(D4="","",IF(IF(K4=0,FALSE(),INDEX(F$2:F$29,K4)=""),"",WORKDAY(MAX(Overview!$B$2-1,Overview!$B$27-1,IF(K4=0,0,INDEX(F$2:F$29,K4)),IFERROR(LOOKUP(2,1/(M$2:M3=M4),P$2:P3),0)),1)))) | F4: =IF(G4>=1,E4,IF(E4="","",WORKDAY(E4,D4-1))) | G4: 1 | H4: =IF(G4>=1,"Done",IF(O4="","Scope pending",IF(E4="","Waiting on dependency",IF(G4>0,"In progress","Planned")))) | I4: =IF(E4="","",INT((E4-Overview!$B$2)/7)+1) | J4: =IF(F4="","",INT((F4-Overview!$B$2)/7)+1) | K4: 2 | L4: 8 | M4: A | N4: 46301 | O4: =IF(AND(Q4<>"",Q4>0),ROUNDUP(Q4/Overview!$B$31,0),IF(OR(L4="",L4<=0,Overview!$B$9<=0),"",ROUNDUP(L4/Overview!$B$9,0))) | P4: =MAX(IFERROR(LOOKUP(2,1/(M$2:M3=M4),P$2:P3),0),IF(G4>=1,0,IF(F4="",0,F4)))
A5: 4 | B5: Homepage | C5: Free user dashboard: Done: signed-in /home (Figma 1898:205770) with live marketplace rows, Coin of the Day (free drawer and Premium upsell modal) and a 3-item Global Catalogue widget | D5: =IF(G5>=1,0,IF(O5="","",ROUNDUP(O5*(1-G5),0))) | E5: =IF(G5>=1,IF(N5="",Overview!$B$27,N5),IF(D5="","",IF(IF(K5=0,FALSE(),INDEX(F$2:F$29,K5)=""),"",WORKDAY(MAX(Overview!$B$2-1,Overview!$B$27-1,IF(K5=0,0,INDEX(F$2:F$29,K5)),IFERROR(LOOKUP(2,1/(M$2:M4=M5),P$2:P4),0)),1)))) | F5: =IF(G5>=1,E5,IF(E5="","",WORKDAY(E5,D5-1))) | G5: 1 | H5: =IF(G5>=1,"Done",IF(O5="","Scope pending",IF(E5="","Waiting on dependency",IF(G5>0,"In progress","Planned")))) | I5: =IF(E5="","",INT((E5-Overview!$B$2)/7)+1) | J5: =IF(F5="","",INT((F5-Overview!$B$2)/7)+1) | K5: 0 | L5: 4 | M5: B | N5: 46301 | O5: =IF(AND(Q5<>"",Q5>0),ROUNDUP(Q5/Overview!$B$31,0),IF(OR(L5="",L5<=0,Overview!$B$9<=0),"",ROUNDUP(L5/Overview!$B$9,0))) | P5: =MAX(IFERROR(LOOKUP(2,1/(M$2:M4=M5),P$2:P4),0),IF(G5>=1,0,IF(F5="",0,F5)))
A6: 5 | B6: Homepage | C6: Premium experience: ~95% test multi-plan purchase (coinzy_premium cookie). JWT + Payments 20 deferred/unscheduled (not QA blocker). | D6: =IF(G6>=1,0,IF(O6="","",ROUNDUP(O6*(1-G6),0))) | E6: =IF(G6>=1,IF(N6="",Overview!$B$27,N6),IF(D6="","",IF(IF(K6=0,FALSE(),INDEX(F$2:F$29,K6)=""),"",WORKDAY(MAX(Overview!$B$2-1,Overview!$B$27-1,IF(K6=0,0,INDEX(F$2:F$29,K6)),IFERROR(LOOKUP(2,1/(M$2:M5=M6),P$2:P5),0)),1)))) | F6: =IF(G6>=1,E6,IF(E6="","",WORKDAY(E6,D6-1))) | G6: 0.95 | H6: =IF(G6>=1,"Done",IF(O6="","Scope pending",IF(E6="","Waiting on dependency",IF(G6>0,"In progress","Planned")))) | I6: =IF(E6="","",INT((E6-Overview!$B$2)/7)+1) | J6: =IF(F6="","",INT((F6-Overview!$B$2)/7)+1) | K6: 4 | M6: B | O6: =IF(AND(Q6<>"",Q6>0),ROUNDUP(Q6/Overview!$B$31,0),IF(OR(L6="",L6<=0,Overview!$B$9<=0),"",ROUNDUP(L6/Overview!$B$9,0))) | P6: =MAX(IFERROR(LOOKUP(2,1/(M$2:M5=M6),P$2:P5),0),IF(G6>=1,0,IF(F6="",0,F6)))
A7: 6 | B7: AI Identification | C7: Start identification: Done: /identify upload (1828:206837), flip-coin (1828:206843), camera + zoom (1828:206846), blocked camera (1828:206844), analyse (1828:206840), failure / not-found (2098:158944), free plan card (1828:206842), error toasts (1493:236892), POST /api/ai/identify-v2; dev black-image debug to force failure | D7: =IF(G7>=1,0,IF(O7="","",ROUNDUP(O7*(1-G7),0))) | E7: =IF(G7>=1,IF(N7="",Overview!$B$27,N7),IF(D7="","",IF(IF(K7=0,FALSE(),INDEX(F$2:F$29,K7)=""),"",WORKDAY(MAX(Overview!$B$2-1,Overview!$B$27-1,IF(K7=0,0,INDEX(F$2:F$29,K7)),IFERROR(LOOKUP(2,1/(M$2:M6=M7),P$2:P6),0)),1)))) | F7: =IF(G7>=1,E7,IF(E7="","",WORKDAY(E7,D7-1))) | G7: 1 | H7: =IF(G7>=1,"Done",IF(O7="","Scope pending",IF(E7="","Waiting on dependency",IF(G7>0,"In progress","Planned")))) | I7: =IF(E7="","",INT((E7-Overview!$B$2)/7)+1) | J7: =IF(F7="","",INT((F7-Overview!$B$2)/7)+1) | K7: 0 | L7: 8 | M7: C | N7: 46301 | O7: =IF(AND(Q7<>"",Q7>0),ROUNDUP(Q7/Overview!$B$31,0),IF(OR(L7="",L7<=0,Overview!$B$9<=0),"",ROUNDUP(L7/Overview!$B$9,0))) | P7: =MAX(IFERROR(LOOKUP(2,1/(M$2:M6=M7),P$2:P6),0),IF(G7>=1,0,IF(F7="",0,F7)))
A8: 7 | B8: AI Identification | C8: Results and actions: Done: matches, result details, collection add, rate-match rail (Figma Solid selected; dummy Feedback sent). | D8: =IF(G8>=1,0,IF(O8="","",ROUNDUP(O8*(1-G8),0))) | E8: =IF(G8>=1,IF(N8="",Overview!$B$27,N8),IF(D8="","",IF(IF(K8=0,FALSE(),INDEX(F$2:F$29,K8)=""),"",WORKDAY(MAX(Overview!$B$2-1,Overview!$B$27-1,IF(K8=0,0,INDEX(F$2:F$29,K8)),IFERROR(LOOKUP(2,1/(M$2:M7=M8),P$2:P7),0)),1)))) | F8: =IF(G8>=1,E8,IF(E8="","",WORKDAY(E8,D8-1))) | G8: 1 | H8: =IF(G8>=1,"Done",IF(O8="","Scope pending",IF(E8="","Waiting on dependency",IF(G8>0,"In progress","Planned")))) | I8: =IF(E8="","",INT((E8-Overview!$B$2)/7)+1) | J8: =IF(F8="","",INT((F8-Overview!$B$2)/7)+1) | K8: 6 | L8: 8 | M8: C | N8: 46304 | O8: =IF(AND(Q8<>"",Q8>0),ROUNDUP(Q8/Overview!$B$31,0),IF(OR(L8="",L8<=0,Overview!$B$9<=0),"",ROUNDUP(L8/Overview!$B$9,0))) | P8: =MAX(IFERROR(LOOKUP(2,1/(M$2:M7=M8),P$2:P7),0),IF(G8>=1,0,IF(F8="",0,F8)))
A9: 8 | B9: Expert evaluation | C9: New request: Done (hub/upload/submit + staff dummy pay). Public credits → Payments 20; landing CTAs → leftover 24. | D9: =IF(G9>=1,0,IF(O9="","",ROUNDUP(O9*(1-G9),0))) | E9: =IF(G9>=1,IF(N9="",Overview!$B$27,N9),IF(D9="","",IF(IF(K9=0,FALSE(),INDEX(F$2:F$29,K9)=""),"",WORKDAY(MAX(Overview!$B$2-1,Overview!$B$27-1,IF(K9=0,0,INDEX(F$2:F$29,K9)),IFERROR(LOOKUP(2,1/(M$2:M8=M9),P$2:P8),0)),1)))) | F9: =IF(G9>=1,E9,IF(E9="","",WORKDAY(E9,D9-1))) | G9: 1 | H9: =IF(G9>=1,"Done",IF(O9="","Scope pending",IF(E9="","Waiting on dependency",IF(G9>0,"In progress","Planned")))) | I9: =IF(E9="","",INT((E9-Overview!$B$2)/7)+1) | J9: =IF(F9="","",INT((F9-Overview!$B$2)/7)+1) | K9: 7 | L9: 6 | M9: C | N9: 46304 | O9: =IF(AND(Q9<>"",Q9>0),ROUNDUP(Q9/Overview!$B$31,0),IF(OR(L9="",L9<=0,Overview!$B$9<=0),"",ROUNDUP(L9/Overview!$B$9,0))) | P9: =MAX(IFERROR(LOOKUP(2,1/(M$2:M8=M9),P$2:P8),0),IF(G9>=1,0,IF(F9="",0,F9)))
A10: 9 | B10: Expert evaluation | C10: Existing requests: Done — list, poll+retry, report+feedback, Socket.IO user-room (REST refresh on events). | D10: =IF(G10>=1,0,IF(O10="","",ROUNDUP(O10*(1-G10),0))) | E10: =IF(G10>=1,IF(N10="",Overview!$B$27,N10),IF(D10="","",IF(IF(K10=0,FALSE(),INDEX(F$2:F$29,K10)=""),"",WORKDAY(MAX(Overview!$B$2-1,Overview!$B$27-1,IF(K10=0,0,INDEX(F$2:F$29,K10)),IFERROR(LOOKUP(2,1/(M$2:M9=M10),P$2:P9),0)),1)))) | F10: =IF(G10>=1,E10,IF(E10="","",WORKDAY(E10,D10-1))) | G10: 1 | H10: =IF(G10>=1,"Done",IF(O10="","Scope pending",IF(E10="","Waiting on dependency",IF(G10>0,"In progress","Planned")))) | I10: =IF(E10="","",INT((E10-Overview!$B$2)/7)+1) | J10: =IF(F10="","",INT((F10-Overview!$B$2)/7)+1) | K10: 8 | L10: 8 | M10: C | N10: 46304 | O10: =IF(AND(Q10<>"",Q10>0),ROUNDUP(Q10/Overview!$B$31,0),IF(OR(L10="",L10<=0,Overview!$B$9<=0),"",ROUNDUP(L10/Overview!$B$9,0))) | P10: =MAX(IFERROR(LOOKUP(2,1/(M$2:M9=M10),P$2:P9),0),IF(G10>=1,0,IF(F10="",0,F10)))
A11: 10 | B11: Global Catalogue | C11: Browse catalogue: Done: live API coin grid, category filters, pagination and name search (?q=, composes with category filters; the API matches whole coin names only; search UI is not in Figma, built on the dashboard search pill) | D11: =IF(G11>=1,0,IF(O11="","",ROUNDUP(O11*(1-G11),0))) | E11: =IF(G11>=1,IF(N11="",Overview!$B$27,N11),IF(D11="","",IF(IF(K11=0,FALSE(),INDEX(F$2:F$29,K11)=""),"",WORKDAY(MAX(Overview!$B$2-1,Overview!$B$27-1,IF(K11=0,0,INDEX(F$2:F$29,K11)),IFERROR(LOOKUP(2,1/(M$2:M10=M11),P$2:P10),0)),1)))) | F11: =IF(G11>=1,E11,IF(E11="","",WORKDAY(E11,D11-1))) | G11: 1 | H11: =IF(G11>=1,"Done",IF(O11="","Scope pending",IF(E11="","Waiting on dependency",IF(G11>0,"In progress","Planned")))) | I11: =IF(E11="","",INT((E11-Overview!$B$2)/7)+1) | J11: =IF(F11="","",INT((F11-Overview!$B$2)/7)+1) | K11: 0 | L11: 6 | M11: D | N11: 46301 | O11: =IF(AND(Q11<>"",Q11>0),ROUNDUP(Q11/Overview!$B$31,0),IF(OR(L11="",L11<=0,Overview!$B$9<=0),"",ROUNDUP(L11/Overview!$B$9,0))) | P11: =MAX(IFERROR(LOOKUP(2,1/(M$2:M10=M11),P$2:P10),0),IF(G11>=1,0,IF(F11="",0,F11)))
A12: 11 | B12: Global Catalogue | C12: Coin details: Done: live API details, grades, tabs; free vs Premium tab gating (1348:137792 / 1341:249499); signed-in app shell; wishlist hearts via PUT/DELETE archetypes/wishlist (grid + details) | D12: =IF(G12>=1,0,IF(O12="","",ROUNDUP(O12*(1-G12),0))) | E12: =IF(G12>=1,IF(N12="",Overview!$B$27,N12),IF(D12="","",IF(IF(K12=0,FALSE(),INDEX(F$2:F$29,K12)=""),"",WORKDAY(MAX(Overview!$B$2-1,Overview!$B$27-1,IF(K12=0,0,INDEX(F$2:F$29,K12)),IFERROR(LOOKUP(2,1/(M$2:M11=M12),P$2:P11),0)),1)))) | F12: =IF(G12>=1,E12,IF(E12="","",WORKDAY(E12,D12-1))) | G12: 1 | H12: =IF(G12>=1,"Done",IF(O12="","Scope pending",IF(E12="","Waiting on dependency",IF(G12>0,"In progress","Planned")))) | I12: =IF(E12="","",INT((E12-Overview!$B$2)/7)+1) | J12: =IF(F12="","",INT((F12-Overview!$B$2)/7)+1) | K12: 10 | L12: 4 | M12: D | N12: 46301 | O12: =IF(AND(Q12<>"",Q12>0),ROUNDUP(Q12/Overview!$B$31,0),IF(OR(L12="",L12<=0,Overview!$B$9<=0),"",ROUNDUP(L12/Overview!$B$9,0))) | P12: =MAX(IFERROR(LOOKUP(2,1/(M$2:M11=M12),P$2:P11),0),IF(G12>=1,0,IF(F12="",0,F12)))
A13: 12 | B13: Marketplace | C13: Browse listings: Done: logged-out landing (793:77834) and category pages (793:77612) with live rows, pagination and title search (?q=, case-insensitive whole words; search UI is not in Figma, built on the dashboard search pill); signed-in /marketplace (1356:154252) with filterItems filters and fetchAll; /home marketplace chips and search; logged-out List a coin → /auth?next= | D13: =IF(G13>=1,0,IF(O13="","",ROUNDUP(O13*(1-G13),0))) | E13: =IF(G13>=1,IF(N13="",Overview!$B$27,N13),IF(D13="","",IF(IF(K13=0,FALSE(),INDEX(F$2:F$29,K13)=""),"",WORKDAY(MAX(Overview!$B$2-1,Overview!$B$27-1,IF(K13=0,0,INDEX(F$2:F$29,K13)),IFERROR(LOOKUP(2,1/(M$2:M12=M13),P$2:P12),0)),1)))) | F13: =IF(G13>=1,E13,IF(E13="","",WORKDAY(E13,D13-1))) | G13: 1 | H13: =IF(G13>=1,"Done",IF(O13="","Scope pending",IF(E13="","Waiting on dependency",IF(G13>0,"In progress","Planned")))) | I13: =IF(E13="","",INT((E13-Overview!$B$2)/7)+1) | J13: =IF(F13="","",INT((F13-Overview!$B$2)/7)+1) | K13: 11 | L13: 6 | M13: D | N13: 46301 | O13: =IF(AND(Q13<>"",Q13>0),ROUNDUP(Q13/Overview!$B$31,0),IF(OR(L13="",L13<=0,Overview!$B$9<=0),"",ROUNDUP(L13/Overview!$B$9,0))) | P13: =MAX(IFERROR(LOOKUP(2,1/(M$2:M12=M13),P$2:P12),0),IF(G13>=1,0,IF(F13="",0,F13)))
A14: 13 | B14: Marketplace | C14: Listing details: Done: live listing, seller details; signed-in Contact seller modal (1356:164759); logged-out redacted contact + /auth?next= (no auth modal) | D14: =IF(G14>=1,0,IF(O14="","",ROUNDUP(O14*(1-G14),0))) | E14: =IF(G14>=1,IF(N14="",Overview!$B$27,N14),IF(D14="","",IF(IF(K14=0,FALSE(),INDEX(F$2:F$29,K14)=""),"",WORKDAY(MAX(Overview!$B$2-1,Overview!$B$27-1,IF(K14=0,0,INDEX(F$2:F$29,K14)),IFERROR(LOOKUP(2,1/(M$2:M13=M14),P$2:P13),0)),1)))) | F14: =IF(G14>=1,E14,IF(E14="","",WORKDAY(E14,D14-1))) | G14: 1 | H14: =IF(G14>=1,"Done",IF(O14="","Scope pending",IF(E14="","Waiting on dependency",IF(G14>0,"In progress","Planned")))) | I14: =IF(E14="","",INT((E14-Overview!$B$2)/7)+1) | J14: =IF(F14="","",INT((F14-Overview!$B$2)/7)+1) | K14: 12 | L14: 4 | M14: D | N14: 46300 | O14: =IF(AND(Q14<>"",Q14>0),ROUNDUP(Q14/Overview!$B$31,0),IF(OR(L14="",L14<=0,Overview!$B$9<=0),"",ROUNDUP(L14/Overview!$B$9,0))) | P14: =MAX(IFERROR(LOOKUP(2,1/(M$2:M13=M14),P$2:P13),0),IF(G14>=1,0,IF(F14="",0,F14)))
A15: 14 | B15: Marketplace | C15: Create listings: Done — List a coin, From Owned, seller profile, Add for Sale, self listing with Remove + Mark as sold (PATCH /marketplace/markSold/:id) | D15: =IF(G15>=1,0,IF(O15="","",ROUNDUP(O15*(1-G15),0))) | E15: =IF(G15>=1,IF(N15="",Overview!$B$27,N15),IF(D15="","",IF(IF(K15=0,FALSE(),INDEX(F$2:F$29,K15)=""),"",WORKDAY(MAX(Overview!$B$2-1,Overview!$B$27-1,IF(K15=0,0,INDEX(F$2:F$29,K15)),IFERROR(LOOKUP(2,1/(M$2:M14=M15),P$2:P14),0)),1)))) | F15: =IF(G15>=1,E15,IF(E15="","",WORKDAY(E15,D15-1))) | G15: 1 | H15: =IF(G15>=1,"Done",IF(O15="","Scope pending",IF(E15="","Waiting on dependency",IF(G15>0,"In progress","Planned")))) | I15: =IF(E15="","",INT((E15-Overview!$B$2)/7)+1) | J15: =IF(F15="","",INT((F15-Overview!$B$2)/7)+1) | K15: 13 | L15: 8 | M15: D | N15: 46304 | O15: =IF(AND(Q15<>"",Q15>0),ROUNDUP(Q15/Overview!$B$31,0),IF(OR(L15="",L15<=0,Overview!$B$9<=0),"",ROUNDUP(L15/Overview!$B$9,0))) | P15: =MAX(IFERROR(LOOKUP(2,1/(M$2:M14=M15),P$2:P14),0),IF(G15>=1,0,IF(F15="",0,F15)))
A16: 15 | B16: Collections | C16: Browse collections: Done — home, bucket/private grids, filters, empty state, coin details; shared catalogue Pagination on grids | D16: =IF(G16>=1,0,IF(O16="","",ROUNDUP(O16*(1-G16),0))) | E16: =IF(G16>=1,IF(N16="",Overview!$B$27,N16),IF(D16="","",IF(IF(K16=0,FALSE(),INDEX(F$2:F$29,K16)=""),"",WORKDAY(MAX(Overview!$B$2-1,Overview!$B$27-1,IF(K16=0,0,INDEX(F$2:F$29,K16)),IFERROR(LOOKUP(2,1/(M$2:M15=M16),P$2:P15),0)),1)))) | F16: =IF(G16>=1,E16,IF(E16="","",WORKDAY(E16,D16-1))) | G16: 1 | H16: =IF(G16>=1,"Done",IF(O16="","Scope pending",IF(E16="","Waiting on dependency",IF(G16>0,"In progress","Planned")))) | I16: =IF(E16="","",INT((E16-Overview!$B$2)/7)+1) | J16: =IF(F16="","",INT((F16-Overview!$B$2)/7)+1) | K16: 7 | L16: 6 | M16: E | N16: 46304 | O16: =IF(AND(Q16<>"",Q16>0),ROUNDUP(Q16/Overview!$B$31,0),IF(OR(L16="",L16<=0,Overview!$B$9<=0),"",ROUNDUP(L16/Overview!$B$9,0))) | P16: =MAX(IFERROR(LOOKUP(2,1/(M$2:M15=M16),P$2:P15),0),IF(G16>=1,0,IF(F16="",0,F16)))
A17: 16 | B17: Collections | C17: Manage collection: Done. Edit/rename + leftover 27 cancelled (out of scope). | D17: =IF(G17>=1,0,IF(O17="","",ROUNDUP(O17*(1-G17),0))) | E17: =IF(G17>=1,IF(N17="",Overview!$B$27,N17),IF(D17="","",IF(IF(K17=0,FALSE(),INDEX(F$2:F$29,K17)=""),"",WORKDAY(MAX(Overview!$B$2-1,Overview!$B$27-1,IF(K17=0,0,INDEX(F$2:F$29,K17)),IFERROR(LOOKUP(2,1/(M$2:M16=M17),P$2:P16),0)),1)))) | F17: =IF(G17>=1,E17,IF(E17="","",WORKDAY(E17,D17-1))) | G17: 1 | H17: =IF(G17>=1,"Done",IF(O17="","Scope pending",IF(E17="","Waiting on dependency",IF(G17>0,"In progress","Planned")))) | I17: =IF(E17="","",INT((E17-Overview!$B$2)/7)+1) | J17: =IF(F17="","",INT((F17-Overview!$B$2)/7)+1) | K17: 15 | L17: 6 | M17: E | N17: 46304 | O17: =IF(AND(Q17<>"",Q17>0),ROUNDUP(Q17/Overview!$B$31,0),IF(OR(L17="",L17<=0,Overview!$B$9<=0),"",ROUNDUP(L17/Overview!$B$9,0))) | P17: =MAX(IFERROR(LOOKUP(2,1/(M$2:M16=M17),P$2:P16),0),IF(G17>=1,0,IF(F17="",0,F17)))
A18: 17 | B18: Feed | C18: Community feed: Done: /feed (Figma Copy 951:87324) — composer, post cards (like/bookmark/⋯ edit·delete), create/edit modal (title+content, max 2 images, Discussion/Buy-Sell), delete confirm, toast; Firebase all-posts + Storage posts/{id}/images (Android PostRepository parity) | D18: =IF(G18>=1,0,IF(O18="","",ROUNDUP(O18*(1-G18),0))) | E18: =IF(G18>=1,IF(N18="",Overview!$B$27,N18),IF(D18="","",IF(IF(K18=0,FALSE(),INDEX(F$2:F$29,K18)=""),"",WORKDAY(MAX(Overview!$B$2-1,Overview!$B$27-1,IF(K18=0,0,INDEX(F$2:F$29,K18)),IFERROR(LOOKUP(2,1/(M$2:M17=M18),P$2:P17),0)),1)))) | F18: =IF(G18>=1,E18,IF(E18="","",WORKDAY(E18,D18-1))) | G18: 1 | H18: =IF(G18>=1,"Done",IF(O18="","Scope pending",IF(E18="","Waiting on dependency",IF(G18>0,"In progress","Planned")))) | I18: =IF(E18="","",INT((E18-Overview!$B$2)/7)+1) | J18: =IF(F18="","",INT((F18-Overview!$B$2)/7)+1) | K18: 5 | L18: 6 | M18: B | N18: 2026-10-09 | O18: =IF(AND(Q18<>"",Q18>0),ROUNDUP(Q18/Overview!$B$31,0),IF(OR(L18="",L18<=0,Overview!$B$9<=0),"",ROUNDUP(L18/Overview!$B$9,0))) | P18: =MAX(IFERROR(LOOKUP(2,1/(M$2:M17=M18),P$2:P17),0),IF(G18>=1,0,IF(F18="",0,F18)))
A19: 18 | B19: Feed | C19: Personal activity: Done: Saved posts + My posts rail; comments/replies modal; inline Notification rail; report; Firestore comments/likes/bookmarks/notifications same paths as Android | D19: =IF(G19>=1,0,IF(O19="","",ROUNDUP(O19*(1-G19),0))) | E19: =IF(G19>=1,IF(N19="",Overview!$B$27,N19),IF(D19="","",IF(IF(K19=0,FALSE(),INDEX(F$2:F$29,K19)=""),"",WORKDAY(MAX(Overview!$B$2-1,Overview!$B$27-1,IF(K19=0,0,INDEX(F$2:F$29,K19)),IFERROR(LOOKUP(2,1/(M$2:M18=M19),P$2:P18),0)),1)))) | F19: =IF(G19>=1,E19,IF(E19="","",WORKDAY(E19,D19-1))) | G19: 1 | H19: =IF(G19>=1,"Done",IF(O19="","Scope pending",IF(E19="","Waiting on dependency",IF(G19>0,"In progress","Planned")))) | I19: =IF(E19="","",INT((E19-Overview!$B$2)/7)+1) | J19: =IF(F19="","",INT((F19-Overview!$B$2)/7)+1) | K19: 17 | L19: 4 | M19: B | N19: 2026-10-09 | O19: =IF(AND(Q19<>"",Q19>0),ROUNDUP(Q19/Overview!$B$31,0),IF(OR(L19="",L19<=0,Overview!$B$9<=0),"",ROUNDUP(L19/Overview!$B$9,0))) | P19: =MAX(IFERROR(LOOKUP(2,1/(M$2:M18=M19),P$2:P18),0),IF(G19>=1,0,IF(F19="",0,F19)))
A20: 19 | B20: Settings | C20: Account settings: Done. Billing entry peeled → leftover task 28 (1h); checkout → Payments 20. | D20: =IF(G20>=1,0,IF(O20="","",ROUNDUP(O20*(1-G20),0))) | E20: =IF(G20>=1,IF(N20="",Overview!$B$27,N20),IF(D20="","",IF(IF(K20=0,FALSE(),INDEX(F$2:F$29,K20)=""),"",WORKDAY(MAX(Overview!$B$2-1,Overview!$B$27-1,IF(K20=0,0,INDEX(F$2:F$29,K20)),IFERROR(LOOKUP(2,1/(M$2:M19=M20),P$2:P19),0)),1)))) | F20: =IF(G20>=1,E20,IF(E20="","",WORKDAY(E20,D20-1))) | G20: 1 | H20: =IF(G20>=1,"Done",IF(O20="","Scope pending",IF(E20="","Waiting on dependency",IF(G20>0,"In progress","Planned")))) | I20: =IF(E20="","",INT((E20-Overview!$B$2)/7)+1) | J20: =IF(F20="","",INT((F20-Overview!$B$2)/7)+1) | K20: 18 | L20: 6 | M20: B | N20: 46304 | O20: =IF(AND(Q20<>"",Q20>0),ROUNDUP(Q20/Overview!$B$31,0),IF(OR(L20="",L20<=0,Overview!$B$9<=0),"",ROUNDUP(L20/Overview!$B$9,0))) | P20: =MAX(IFERROR(LOOKUP(2,1/(M$2:M19=M20),P$2:P19),0),IF(G20>=1,0,IF(F20="",0,F20)))
A21: 20 | B21: Payments (deferred) | C21: Payments DEFERRED: Experts web credits + Premium checkout + Plan & billing. | D21: =IF(G21>=1,0,IF(O21="","",ROUNDUP(O21*(1-G21),0))) | E21: =IF(G21>=1,IF(N21="",Overview!$B$27,N21),IF(D21="","",IF(IF(K21=0,FALSE(),INDEX(F$2:F$29,K21)=""),"",WORKDAY(MAX(Overview!$B$2-1,Overview!$B$27-1,IF(K21=0,0,INDEX(F$2:F$29,K21)),IFERROR(LOOKUP(2,1/(M$2:M20=M21),P$2:P20),0)),1)))) | F21: =IF(G21>=1,E21,IF(E21="","",WORKDAY(E21,D21-1))) | G21: 0 | H21: =IF(G21>=1,"Done",IF(O21="","Scope pending",IF(E21="","Waiting on dependency",IF(G21>0,"In progress","Planned")))) | I21: =IF(E21="","",INT((E21-Overview!$B$2)/7)+1) | J21: =IF(F21="","",INT((F21-Overview!$B$2)/7)+1) | K21: 3 | M21: A | O21: =IF(AND(Q21<>"",Q21>0),ROUNDUP(Q21/Overview!$B$31,0),IF(OR(L21="",L21<=0,Overview!$B$9<=0),"",ROUNDUP(L21/Overview!$B$9,0))) | P21: =MAX(IFERROR(LOOKUP(2,1/(M$2:M20=M21),P$2:P20),0),IF(G21>=1,0,IF(F21="",0,F21)))
A22: 21 | B22: Payments (deferred) | C22: Folded into task 20 — deferred payments (unscheduled). | D22: =IF(G22>=1,0,IF(O22="","",ROUNDUP(O22*(1-G22),0))) | E22: =IF(G22>=1,IF(N22="",Overview!$B$27,N22),IF(D22="","",IF(IF(K22=0,FALSE(),INDEX(F$2:F$29,K22)=""),"",WORKDAY(MAX(Overview!$B$2-1,Overview!$B$27-1,IF(K22=0,0,INDEX(F$2:F$29,K22)),IFERROR(LOOKUP(2,1/(M$2:M21=M22),P$2:P21),0)),1)))) | F22: =IF(G22>=1,E22,IF(E22="","",WORKDAY(E22,D22-1))) | G22: 0 | H22: =IF(G22>=1,"Done",IF(O22="","Scope pending",IF(E22="","Waiting on dependency",IF(G22>0,"In progress","Planned")))) | I22: =IF(E22="","",INT((E22-Overview!$B$2)/7)+1) | J22: =IF(F22="","",INT((F22-Overview!$B$2)/7)+1) | K22: 20 | M22: A | O22: =IF(AND(Q22<>"",Q22>0),ROUNDUP(Q22/Overview!$B$31,0),IF(OR(L22="",L22<=0,Overview!$B$9<=0),"",ROUNDUP(L22/Overview!$B$9,0))) | P22: =MAX(IFERROR(LOOKUP(2,1/(M$2:M21=M22),P$2:P21),0),IF(G22>=1,0,IF(F22="",0,F22)))
A23: 22 | B23: Review and fixes | C23: E2E QA + ClickUp bug backlog: 13 fixed / 34 pts on 2026-10-28; 63 open / 147 pts → ~5 agent days (40h) at 34 pts/day. british-coins empty chip + other-apps Coming soon intentional. | D23: =IF(G23>=1,0,IF(O23="","",ROUNDUP(O23*(1-G23),0))) | E23: =IF(G23>=1,IF(N23="",Overview!$B$27,N23),IF(D23="","",IF(COUNTIF(H2:H22,"Waiting on dependency")+COUNTIF(H24:H29,"Waiting on dependency")>0,"",WORKDAY(MAX(Overview!$B$2-1,Overview!$B$27-1,MAX(F2:F22,F24:F29)),1)))) | F23: =IF(G23>=1,E23,IF(E23="","",WORKDAY(E23,D23-1))) | G23: 0 | H23: =IF(G23>=1,"Done",IF(O23="","Scope pending",IF(E23="","Waiting on dependency",IF(G23>0,"In progress","Planned")))) | I23: =IF(E23="","",INT((E23-Overview!$B$2)/7)+1) | J23: =IF(F23="","",INT((F23-Overview!$B$2)/7)+1) | K23: 0 | M23: QA | O23: =IF(AND(Q23<>"",Q23>0),ROUNDUP(Q23/Overview!$B$31,0),IF(OR(L23="",L23<=0,Overview!$B$9<=0),"",ROUNDUP(L23/Overview!$B$9,0))) | P23: =MAX(IFERROR(LOOKUP(2,1/(M$2:M22=M23),P$2:P22),0),IF(G23>=1,0,IF(F23="",0,F23))) | Q23: 40
A24: 23 | B24: Blogs | C24: Blog experience: Done: six articles, category filtering and load more; duration unscheduled | D24: =IF(G24>=1,0,IF(O24="","",ROUNDUP(O24*(1-G24),0))) | E24: =IF(G24>=1,IF(N24="",Overview!$B$27,N24),IF(D24="","",IF(IF(K24=0,FALSE(),INDEX(F$2:F$29,K24)=""),"",WORKDAY(MAX(Overview!$B$2-1,Overview!$B$27-1,IF(K24=0,0,INDEX(F$2:F$29,K24)),IFERROR(LOOKUP(2,1/(M$2:M23=M24),P$2:P23),0)),1)))) | F24: =IF(G24>=1,E24,IF(E24="","",WORKDAY(E24,D24-1))) | G24: 1 | H24: =IF(G24>=1,"Done",IF(O24="","Scope pending",IF(E24="","Waiting on dependency",IF(G24>0,"In progress","Planned")))) | I24: =IF(E24="","",INT((E24-Overview!$B$2)/7)+1) | J24: =IF(F24="","",INT((F24-Overview!$B$2)/7)+1) | K24: Parallel | N24: 46300 | O24: =IF(AND(Q24<>"",Q24>0),ROUNDUP(Q24/Overview!$B$31,0),IF(OR(L24="",L24<=0,Overview!$B$9<=0),"",ROUNDUP(L24/Overview!$B$9,0))) | P24: =MAX(IFERROR(LOOKUP(2,1/(M$2:M23=M24),P$2:P23),0),IF(G24>=1,0,IF(F24="",0,F24)))
A25: 24 | B25: Leftovers (hours) | C25: Landing Expert CTAs: Done — Get Expert’s opinion? / View all → /auth?next=/experts | D25: =IF(G25>=1,0,IF(O25="","",ROUNDUP(O25*(1-G25),0))) | E25: =IF(G25>=1,IF(N25="",Overview!$B$27,N25),IF(D25="","",IF(IF(K25=0,FALSE(),INDEX(F$2:F$29,K25)=""),"",WORKDAY(MAX(Overview!$B$2-1,Overview!$B$27-1,IF(K25=0,0,INDEX(F$2:F$29,K25)),IFERROR(LOOKUP(2,1/(M$2:M24=M25),P$2:P24),0)),1)))) | F25: =IF(G25>=1,E25,IF(E25="","",WORKDAY(E25,D25-1))) | G25: 1 | H25: =IF(G25>=1,"Done",IF(O25="","Scope pending",IF(E25="","Waiting on dependency",IF(G25>0,"In progress","Planned")))) | I25: =IF(E25="","",INT((E25-Overview!$B$2)/7)+1) | J25: =IF(F25="","",INT((F25-Overview!$B$2)/7)+1) | K25: 2 | M25: A | N25: 46304 | O25: =IF(AND(Q25<>"",Q25>0),ROUNDUP(Q25/Overview!$B$31,0),IF(OR(L25="",L25<=0,Overview!$B$9<=0),"",ROUNDUP(L25/Overview!$B$9,0))) | P25: =MAX(IFERROR(LOOKUP(2,1/(M$2:M24=M25),P$2:P24),0),IF(G25>=1,0,IF(F25="",0,F25))) | Q25: 1
A26: 25 | B26: Leftovers (hours) | C26: Identify rate-match: Done — Figma rate card (Stroke + Solid primary selected) + Message/Submit; dummy Feedback sent toast (no API). | D26: =IF(G26>=1,0,IF(O26="","",ROUNDUP(O26*(1-G26),0))) | E26: =IF(G26>=1,IF(N26="",Overview!$B$27,N26),IF(D26="","",IF(IF(K26=0,FALSE(),INDEX(F$2:F$29,K26)=""),"",WORKDAY(MAX(Overview!$B$2-1,Overview!$B$27-1,IF(K26=0,0,INDEX(F$2:F$29,K26)),IFERROR(LOOKUP(2,1/(M$2:M25=M26),P$2:P25),0)),1)))) | F26: =IF(G26>=1,E26,IF(E26="","",WORKDAY(E26,D26-1))) | G26: 1 | H26: =IF(G26>=1,"Done",IF(O26="","Scope pending",IF(E26="","Waiting on dependency",IF(G26>0,"In progress","Planned")))) | I26: =IF(E26="","",INT((E26-Overview!$B$2)/7)+1) | J26: =IF(F26="","",INT((F26-Overview!$B$2)/7)+1) | K26: 7 | M26: C | N26: 46309 | O26: =IF(AND(Q26<>"",Q26>0),ROUNDUP(Q26/Overview!$B$31,0),IF(OR(L26="",L26<=0,Overview!$B$9<=0),"",ROUNDUP(L26/Overview!$B$9,0))) | P26: =MAX(IFERROR(LOOKUP(2,1/(M$2:M25=M26),P$2:P25),0),IF(G26>=1,0,IF(F26="",0,F26))) | Q26: 3
A27: 26 | B27: Leftovers (hours) | C27: Experts Socket.IO: Done — socket.io-client → Experts host auth.userId; events trigger REST refresh / router.refresh. Poll kept as fallback. | D27: =IF(G27>=1,0,IF(O27="","",ROUNDUP(O27*(1-G27),0))) | E27: =IF(G27>=1,IF(N27="",Overview!$B$27,N27),IF(D27="","",IF(IF(K27=0,FALSE(),INDEX(F$2:F$29,K27)=""),"",WORKDAY(MAX(Overview!$B$2-1,Overview!$B$27-1,IF(K27=0,0,INDEX(F$2:F$29,K27)),IFERROR(LOOKUP(2,1/(M$2:M26=M27),P$2:P26),0)),1)))) | F27: =IF(G27>=1,E27,IF(E27="","",WORKDAY(E27,D27-1))) | G27: 1 | H27: =IF(G27>=1,"Done",IF(O27="","Scope pending",IF(E27="","Waiting on dependency",IF(G27>0,"In progress","Planned")))) | I27: =IF(E27="","",INT((E27-Overview!$B$2)/7)+1) | J27: =IF(F27="","",INT((F27-Overview!$B$2)/7)+1) | K27: 9 | M27: C | N27: 46309 | O27: =IF(AND(Q27<>"",Q27>0),ROUNDUP(Q27/Overview!$B$31,0),IF(OR(L27="",L27<=0,Overview!$B$9<=0),"",ROUNDUP(L27/Overview!$B$9,0))) | P27: =MAX(IFERROR(LOOKUP(2,1/(M$2:M26=M27),P$2:P26),0),IF(G27>=1,0,IF(F27="",0,F27))) | Q27: 8
A28: 27 | B28: Leftovers (hours) | C28: (cancelled — was manage polish): Out of scope. Edit/rename private not on web. ID kept. | D28: =IF(G28>=1,0,IF(O28="","",ROUNDUP(O28*(1-G28),0))) | E28: =IF(G28>=1,IF(N28="",Overview!$B$27,N28),IF(D28="","",IF(IF(K28=0,FALSE(),INDEX(F$2:F$29,K28)=""),"",WORKDAY(MAX(Overview!$B$2-1,Overview!$B$27-1,IF(K28=0,0,INDEX(F$2:F$29,K28)),IFERROR(LOOKUP(2,1/(M$2:M27=M28),P$2:P27),0)),1)))) | F28: =IF(G28>=1,E28,IF(E28="","",WORKDAY(E28,D28-1))) | G28: 1 | H28: =IF(G28>=1,"Done",IF(O28="","Scope pending",IF(E28="","Waiting on dependency",IF(G28>0,"In progress","Planned")))) | I28: =IF(E28="","",INT((E28-Overview!$B$2)/7)+1) | J28: =IF(F28="","",INT((F28-Overview!$B$2)/7)+1) | K28: 0 | M28: E | N28: 46304 | O28: =IF(AND(Q28<>"",Q28>0),ROUNDUP(Q28/Overview!$B$31,0),IF(OR(L28="",L28<=0,Overview!$B$9<=0),"",ROUNDUP(L28/Overview!$B$9,0))) | P28: =MAX(IFERROR(LOOKUP(2,1/(M$2:M27=M28),P$2:P27),0),IF(G28>=1,0,IF(F28="",0,F28)))
A29: 28 | B29: Leftovers (hours) | C29: Settings billing entry: Done — opens test Premium plans. Real gateway → Payments 20. | D29: =IF(G29>=1,0,IF(O29="","",ROUNDUP(O29*(1-G29),0))) | E29: =IF(G29>=1,IF(N29="",Overview!$B$27,N29),IF(D29="","",IF(IF(K29=0,FALSE(),INDEX(F$2:F$29,K29)=""),"",WORKDAY(MAX(Overview!$B$2-1,Overview!$B$27-1,IF(K29=0,0,INDEX(F$2:F$29,K29)),IFERROR(LOOKUP(2,1/(M$2:M28=M29),P$2:P28),0)),1)))) | F29: =IF(G29>=1,E29,IF(E29="","",WORKDAY(E29,D29-1))) | G29: 1 | H29: =IF(G29>=1,"Done",IF(O29="","Scope pending",IF(E29="","Waiting on dependency",IF(G29>0,"In progress","Planned")))) | I29: =IF(E29="","",INT((E29-Overview!$B$2)/7)+1) | J29: =IF(F29="","",INT((F29-Overview!$B$2)/7)+1) | K29: 19 | M29: B | N29: 46309 | O29: =IF(AND(Q29<>"",Q29>0),ROUNDUP(Q29/Overview!$B$31,0),IF(OR(L29="",L29<=0,Overview!$B$9<=0),"",ROUNDUP(L29/Overview!$B$9,0))) | P29: =MAX(IFERROR(LOOKUP(2,1/(M$2:M28=M29),P$2:P28),0),IF(G29>=1,0,IF(F29="",0,F29))) | Q29: 1

Sheet Weekly View
A1: ID | B1: Section | C1: Work package | D1: Week 1 | E1: Week 2 | F1: Week 3 | G1: Week 4 | H1: Week 5 | I1: Week 6 | J1: Week 7 | K1: Week 8 | L1: Week 9 | M1: Week 10 | N1: Week 11 | O1: Week 12 | P1: Week 13 | Q1: Week 14 | R1: Week 15 | S1: Week 16 | T1: Week 17 | U1: Week 18 | V1: Week 19 | W1: Week 20 | X1: Week 21 | Y1: Week 22 | Z1: Week 23 | AA1: Week 24 | AB1: Week 25 | AC1: Week 26
A2: ='Detailed Timeline'!A2 | B2: ='Detailed Timeline'!B2 | C2: ='Detailed Timeline'!C2 | D2: =IF(OR('Detailed Timeline'!$I2="",'Detailed Timeline'!$J2=""),"",IF(AND(1>='Detailed Timeline'!$I2,1<='Detailed Timeline'!$J2),"■","")) | E2: =IF(OR('Detailed Timeline'!$I2="",'Detailed Timeline'!$J2=""),"",IF(AND(2>='Detailed Timeline'!$I2,2<='Detailed Timeline'!$J2),"■","")) | F2: =IF(OR('Detailed Timeline'!$I2="",'Detailed Timeline'!$J2=""),"",IF(AND(3>='Detailed Timeline'!$I2,3<='Detailed Timeline'!$J2),"■","")) | G2: =IF(OR('Detailed Timeline'!$I2="",'Detailed Timeline'!$J2=""),"",IF(AND(4>='Detailed Timeline'!$I2,4<='Detailed Timeline'!$J2),"■","")) | H2: =IF(OR('Detailed Timeline'!$I2="",'Detailed Timeline'!$J2=""),"",IF(AND(5>='Detailed Timeline'!$I2,5<='Detailed Timeline'!$J2),"■","")) | I2: =IF(OR('Detailed Timeline'!$I2="",'Detailed Timeline'!$J2=""),"",IF(AND(6>='Detailed Timeline'!$I2,6<='Detailed Timeline'!$J2),"■","")) | J2: =IF(OR('Detailed Timeline'!$I2="",'Detailed Timeline'!$J2=""),"",IF(AND(7>='Detailed Timeline'!$I2,7<='Detailed Timeline'!$J2),"■","")) | K2: =IF(OR('Detailed Timeline'!$I2="",'Detailed Timeline'!$J2=""),"",IF(AND(8>='Detailed Timeline'!$I2,8<='Detailed Timeline'!$J2),"■","")) | L2: =IF(OR('Detailed Timeline'!$I2="",'Detailed Timeline'!$J2=""),"",IF(AND(9>='Detailed Timeline'!$I2,9<='Detailed Timeline'!$J2),"■","")) | M2: =IF(OR('Detailed Timeline'!$I2="",'Detailed Timeline'!$J2=""),"",IF(AND(10>='Detailed Timeline'!$I2,10<='Detailed Timeline'!$J2),"■","")) | N2: =IF(OR('Detailed Timeline'!$I2="",'Detailed Timeline'!$J2=""),"",IF(AND(11>='Detailed Timeline'!$I2,11<='Detailed Timeline'!$J2),"■","")) | O2: =IF(OR('Detailed Timeline'!$I2="",'Detailed Timeline'!$J2=""),"",IF(AND(12>='Detailed Timeline'!$I2,12<='Detailed Timeline'!$J2),"■","")) | P2: =IF(OR('Detailed Timeline'!$I2="",'Detailed Timeline'!$J2=""),"",IF(AND(13>='Detailed Timeline'!$I2,13<='Detailed Timeline'!$J2),"■","")) | Q2: =IF(OR('Detailed Timeline'!$I2="",'Detailed Timeline'!$J2=""),"",IF(AND(14>='Detailed Timeline'!$I2,14<='Detailed Timeline'!$J2),"■","")) | R2: =IF(OR('Detailed Timeline'!$I2="",'Detailed Timeline'!$J2=""),"",IF(AND(15>='Detailed Timeline'!$I2,15<='Detailed Timeline'!$J2),"■","")) | S2: =IF(OR('Detailed Timeline'!$I2="",'Detailed Timeline'!$J2=""),"",IF(AND(16>='Detailed Timeline'!$I2,16<='Detailed Timeline'!$J2),"■","")) | T2: =IF(OR('Detailed Timeline'!$I2="",'Detailed Timeline'!$J2=""),"",IF(AND(17>='Detailed Timeline'!$I2,17<='Detailed Timeline'!$J2),"■","")) | U2: =IF(OR('Detailed Timeline'!$I2="",'Detailed Timeline'!$J2=""),"",IF(AND(18>='Detailed Timeline'!$I2,18<='Detailed Timeline'!$J2),"■","")) | V2: =IF(OR('Detailed Timeline'!$I2="",'Detailed Timeline'!$J2=""),"",IF(AND(19>='Detailed Timeline'!$I2,19<='Detailed Timeline'!$J2),"■","")) | W2: =IF(OR('Detailed Timeline'!$I2="",'Detailed Timeline'!$J2=""),"",IF(AND(20>='Detailed Timeline'!$I2,20<='Detailed Timeline'!$J2),"■","")) | X2: =IF(OR('Detailed Timeline'!$I2="",'Detailed Timeline'!$J2=""),"",IF(AND(21>='Detailed Timeline'!$I2,21<='Detailed Timeline'!$J2),"■","")) | Y2: =IF(OR('Detailed Timeline'!$I2="",'Detailed Timeline'!$J2=""),"",IF(AND(22>='Detailed Timeline'!$I2,22<='Detailed Timeline'!$J2),"■","")) | Z2: =IF(OR('Detailed Timeline'!$I2="",'Detailed Timeline'!$J2=""),"",IF(AND(23>='Detailed Timeline'!$I2,23<='Detailed Timeline'!$J2),"■","")) | AA2: =IF(OR('Detailed Timeline'!$I2="",'Detailed Timeline'!$J2=""),"",IF(AND(24>='Detailed Timeline'!$I2,24<='Detailed Timeline'!$J2),"■","")) | AB2: =IF(OR('Detailed Timeline'!$I2="",'Detailed Timeline'!$J2=""),"",IF(AND(25>='Detailed Timeline'!$I2,25<='Detailed Timeline'!$J2),"■","")) | AC2: =IF(OR('Detailed Timeline'!$I2="",'Detailed Timeline'!$J2=""),"",IF(AND(26>='Detailed Timeline'!$I2,26<='Detailed Timeline'!$J2),"■",""))
A3: ='Detailed Timeline'!A3 | B3: ='Detailed Timeline'!B3 | C3: ='Detailed Timeline'!C3 | D3: =IF(OR('Detailed Timeline'!$I3="",'Detailed Timeline'!$J3=""),"",IF(AND(1>='Detailed Timeline'!$I3,1<='Detailed Timeline'!$J3),"■","")) | E3: =IF(OR('Detailed Timeline'!$I3="",'Detailed Timeline'!$J3=""),"",IF(AND(2>='Detailed Timeline'!$I3,2<='Detailed Timeline'!$J3),"■","")) | F3: =IF(OR('Detailed Timeline'!$I3="",'Detailed Timeline'!$J3=""),"",IF(AND(3>='Detailed Timeline'!$I3,3<='Detailed Timeline'!$J3),"■","")) | G3: =IF(OR('Detailed Timeline'!$I3="",'Detailed Timeline'!$J3=""),"",IF(AND(4>='Detailed Timeline'!$I3,4<='Detailed Timeline'!$J3),"■","")) | H3: =IF(OR('Detailed Timeline'!$I3="",'Detailed Timeline'!$J3=""),"",IF(AND(5>='Detailed Timeline'!$I3,5<='Detailed Timeline'!$J3),"■","")) | I3: =IF(OR('Detailed Timeline'!$I3="",'Detailed Timeline'!$J3=""),"",IF(AND(6>='Detailed Timeline'!$I3,6<='Detailed Timeline'!$J3),"■","")) | J3: =IF(OR('Detailed Timeline'!$I3="",'Detailed Timeline'!$J3=""),"",IF(AND(7>='Detailed Timeline'!$I3,7<='Detailed Timeline'!$J3),"■","")) | K3: =IF(OR('Detailed Timeline'!$I3="",'Detailed Timeline'!$J3=""),"",IF(AND(8>='Detailed Timeline'!$I3,8<='Detailed Timeline'!$J3),"■","")) | L3: =IF(OR('Detailed Timeline'!$I3="",'Detailed Timeline'!$J3=""),"",IF(AND(9>='Detailed Timeline'!$I3,9<='Detailed Timeline'!$J3),"■","")) | M3: =IF(OR('Detailed Timeline'!$I3="",'Detailed Timeline'!$J3=""),"",IF(AND(10>='Detailed Timeline'!$I3,10<='Detailed Timeline'!$J3),"■","")) | N3: =IF(OR('Detailed Timeline'!$I3="",'Detailed Timeline'!$J3=""),"",IF(AND(11>='Detailed Timeline'!$I3,11<='Detailed Timeline'!$J3),"■","")) | O3: =IF(OR('Detailed Timeline'!$I3="",'Detailed Timeline'!$J3=""),"",IF(AND(12>='Detailed Timeline'!$I3,12<='Detailed Timeline'!$J3),"■","")) | P3: =IF(OR('Detailed Timeline'!$I3="",'Detailed Timeline'!$J3=""),"",IF(AND(13>='Detailed Timeline'!$I3,13<='Detailed Timeline'!$J3),"■","")) | Q3: =IF(OR('Detailed Timeline'!$I3="",'Detailed Timeline'!$J3=""),"",IF(AND(14>='Detailed Timeline'!$I3,14<='Detailed Timeline'!$J3),"■","")) | R3: =IF(OR('Detailed Timeline'!$I3="",'Detailed Timeline'!$J3=""),"",IF(AND(15>='Detailed Timeline'!$I3,15<='Detailed Timeline'!$J3),"■","")) | S3: =IF(OR('Detailed Timeline'!$I3="",'Detailed Timeline'!$J3=""),"",IF(AND(16>='Detailed Timeline'!$I3,16<='Detailed Timeline'!$J3),"■","")) | T3: =IF(OR('Detailed Timeline'!$I3="",'Detailed Timeline'!$J3=""),"",IF(AND(17>='Detailed Timeline'!$I3,17<='Detailed Timeline'!$J3),"■","")) | U3: =IF(OR('Detailed Timeline'!$I3="",'Detailed Timeline'!$J3=""),"",IF(AND(18>='Detailed Timeline'!$I3,18<='Detailed Timeline'!$J3),"■","")) | V3: =IF(OR('Detailed Timeline'!$I3="",'Detailed Timeline'!$J3=""),"",IF(AND(19>='Detailed Timeline'!$I3,19<='Detailed Timeline'!$J3),"■","")) | W3: =IF(OR('Detailed Timeline'!$I3="",'Detailed Timeline'!$J3=""),"",IF(AND(20>='Detailed Timeline'!$I3,20<='Detailed Timeline'!$J3),"■","")) | X3: =IF(OR('Detailed Timeline'!$I3="",'Detailed Timeline'!$J3=""),"",IF(AND(21>='Detailed Timeline'!$I3,21<='Detailed Timeline'!$J3),"■","")) | Y3: =IF(OR('Detailed Timeline'!$I3="",'Detailed Timeline'!$J3=""),"",IF(AND(22>='Detailed Timeline'!$I3,22<='Detailed Timeline'!$J3),"■","")) | Z3: =IF(OR('Detailed Timeline'!$I3="",'Detailed Timeline'!$J3=""),"",IF(AND(23>='Detailed Timeline'!$I3,23<='Detailed Timeline'!$J3),"■","")) | AA3: =IF(OR('Detailed Timeline'!$I3="",'Detailed Timeline'!$J3=""),"",IF(AND(24>='Detailed Timeline'!$I3,24<='Detailed Timeline'!$J3),"■","")) | AB3: =IF(OR('Detailed Timeline'!$I3="",'Detailed Timeline'!$J3=""),"",IF(AND(25>='Detailed Timeline'!$I3,25<='Detailed Timeline'!$J3),"■","")) | AC3: =IF(OR('Detailed Timeline'!$I3="",'Detailed Timeline'!$J3=""),"",IF(AND(26>='Detailed Timeline'!$I3,26<='Detailed Timeline'!$J3),"■",""))
A4: ='Detailed Timeline'!A4 | B4: ='Detailed Timeline'!B4 | C4: ='Detailed Timeline'!C4 | D4: =IF(OR('Detailed Timeline'!$I4="",'Detailed Timeline'!$J4=""),"",IF(AND(1>='Detailed Timeline'!$I4,1<='Detailed Timeline'!$J4),"■","")) | E4: =IF(OR('Detailed Timeline'!$I4="",'Detailed Timeline'!$J4=""),"",IF(AND(2>='Detailed Timeline'!$I4,2<='Detailed Timeline'!$J4),"■","")) | F4: =IF(OR('Detailed Timeline'!$I4="",'Detailed Timeline'!$J4=""),"",IF(AND(3>='Detailed Timeline'!$I4,3<='Detailed Timeline'!$J4),"■","")) | G4: =IF(OR('Detailed Timeline'!$I4="",'Detailed Timeline'!$J4=""),"",IF(AND(4>='Detailed Timeline'!$I4,4<='Detailed Timeline'!$J4),"■","")) | H4: =IF(OR('Detailed Timeline'!$I4="",'Detailed Timeline'!$J4=""),"",IF(AND(5>='Detailed Timeline'!$I4,5<='Detailed Timeline'!$J4),"■","")) | I4: =IF(OR('Detailed Timeline'!$I4="",'Detailed Timeline'!$J4=""),"",IF(AND(6>='Detailed Timeline'!$I4,6<='Detailed Timeline'!$J4),"■","")) | J4: =IF(OR('Detailed Timeline'!$I4="",'Detailed Timeline'!$J4=""),"",IF(AND(7>='Detailed Timeline'!$I4,7<='Detailed Timeline'!$J4),"■","")) | K4: =IF(OR('Detailed Timeline'!$I4="",'Detailed Timeline'!$J4=""),"",IF(AND(8>='Detailed Timeline'!$I4,8<='Detailed Timeline'!$J4),"■","")) | L4: =IF(OR('Detailed Timeline'!$I4="",'Detailed Timeline'!$J4=""),"",IF(AND(9>='Detailed Timeline'!$I4,9<='Detailed Timeline'!$J4),"■","")) | M4: =IF(OR('Detailed Timeline'!$I4="",'Detailed Timeline'!$J4=""),"",IF(AND(10>='Detailed Timeline'!$I4,10<='Detailed Timeline'!$J4),"■","")) | N4: =IF(OR('Detailed Timeline'!$I4="",'Detailed Timeline'!$J4=""),"",IF(AND(11>='Detailed Timeline'!$I4,11<='Detailed Timeline'!$J4),"■","")) | O4: =IF(OR('Detailed Timeline'!$I4="",'Detailed Timeline'!$J4=""),"",IF(AND(12>='Detailed Timeline'!$I4,12<='Detailed Timeline'!$J4),"■","")) | P4: =IF(OR('Detailed Timeline'!$I4="",'Detailed Timeline'!$J4=""),"",IF(AND(13>='Detailed Timeline'!$I4,13<='Detailed Timeline'!$J4),"■","")) | Q4: =IF(OR('Detailed Timeline'!$I4="",'Detailed Timeline'!$J4=""),"",IF(AND(14>='Detailed Timeline'!$I4,14<='Detailed Timeline'!$J4),"■","")) | R4: =IF(OR('Detailed Timeline'!$I4="",'Detailed Timeline'!$J4=""),"",IF(AND(15>='Detailed Timeline'!$I4,15<='Detailed Timeline'!$J4),"■","")) | S4: =IF(OR('Detailed Timeline'!$I4="",'Detailed Timeline'!$J4=""),"",IF(AND(16>='Detailed Timeline'!$I4,16<='Detailed Timeline'!$J4),"■","")) | T4: =IF(OR('Detailed Timeline'!$I4="",'Detailed Timeline'!$J4=""),"",IF(AND(17>='Detailed Timeline'!$I4,17<='Detailed Timeline'!$J4),"■","")) | U4: =IF(OR('Detailed Timeline'!$I4="",'Detailed Timeline'!$J4=""),"",IF(AND(18>='Detailed Timeline'!$I4,18<='Detailed Timeline'!$J4),"■","")) | V4: =IF(OR('Detailed Timeline'!$I4="",'Detailed Timeline'!$J4=""),"",IF(AND(19>='Detailed Timeline'!$I4,19<='Detailed Timeline'!$J4),"■","")) | W4: =IF(OR('Detailed Timeline'!$I4="",'Detailed Timeline'!$J4=""),"",IF(AND(20>='Detailed Timeline'!$I4,20<='Detailed Timeline'!$J4),"■","")) | X4: =IF(OR('Detailed Timeline'!$I4="",'Detailed Timeline'!$J4=""),"",IF(AND(21>='Detailed Timeline'!$I4,21<='Detailed Timeline'!$J4),"■","")) | Y4: =IF(OR('Detailed Timeline'!$I4="",'Detailed Timeline'!$J4=""),"",IF(AND(22>='Detailed Timeline'!$I4,22<='Detailed Timeline'!$J4),"■","")) | Z4: =IF(OR('Detailed Timeline'!$I4="",'Detailed Timeline'!$J4=""),"",IF(AND(23>='Detailed Timeline'!$I4,23<='Detailed Timeline'!$J4),"■","")) | AA4: =IF(OR('Detailed Timeline'!$I4="",'Detailed Timeline'!$J4=""),"",IF(AND(24>='Detailed Timeline'!$I4,24<='Detailed Timeline'!$J4),"■","")) | AB4: =IF(OR('Detailed Timeline'!$I4="",'Detailed Timeline'!$J4=""),"",IF(AND(25>='Detailed Timeline'!$I4,25<='Detailed Timeline'!$J4),"■","")) | AC4: =IF(OR('Detailed Timeline'!$I4="",'Detailed Timeline'!$J4=""),"",IF(AND(26>='Detailed Timeline'!$I4,26<='Detailed Timeline'!$J4),"■",""))
A5: ='Detailed Timeline'!A5 | B5: ='Detailed Timeline'!B5 | C5: ='Detailed Timeline'!C5 | D5: =IF(OR('Detailed Timeline'!$I5="",'Detailed Timeline'!$J5=""),"",IF(AND(1>='Detailed Timeline'!$I5,1<='Detailed Timeline'!$J5),"■","")) | E5: =IF(OR('Detailed Timeline'!$I5="",'Detailed Timeline'!$J5=""),"",IF(AND(2>='Detailed Timeline'!$I5,2<='Detailed Timeline'!$J5),"■","")) | F5: =IF(OR('Detailed Timeline'!$I5="",'Detailed Timeline'!$J5=""),"",IF(AND(3>='Detailed Timeline'!$I5,3<='Detailed Timeline'!$J5),"■","")) | G5: =IF(OR('Detailed Timeline'!$I5="",'Detailed Timeline'!$J5=""),"",IF(AND(4>='Detailed Timeline'!$I5,4<='Detailed Timeline'!$J5),"■","")) | H5: =IF(OR('Detailed Timeline'!$I5="",'Detailed Timeline'!$J5=""),"",IF(AND(5>='Detailed Timeline'!$I5,5<='Detailed Timeline'!$J5),"■","")) | I5: =IF(OR('Detailed Timeline'!$I5="",'Detailed Timeline'!$J5=""),"",IF(AND(6>='Detailed Timeline'!$I5,6<='Detailed Timeline'!$J5),"■","")) | J5: =IF(OR('Detailed Timeline'!$I5="",'Detailed Timeline'!$J5=""),"",IF(AND(7>='Detailed Timeline'!$I5,7<='Detailed Timeline'!$J5),"■","")) | K5: =IF(OR('Detailed Timeline'!$I5="",'Detailed Timeline'!$J5=""),"",IF(AND(8>='Detailed Timeline'!$I5,8<='Detailed Timeline'!$J5),"■","")) | L5: =IF(OR('Detailed Timeline'!$I5="",'Detailed Timeline'!$J5=""),"",IF(AND(9>='Detailed Timeline'!$I5,9<='Detailed Timeline'!$J5),"■","")) | M5: =IF(OR('Detailed Timeline'!$I5="",'Detailed Timeline'!$J5=""),"",IF(AND(10>='Detailed Timeline'!$I5,10<='Detailed Timeline'!$J5),"■","")) | N5: =IF(OR('Detailed Timeline'!$I5="",'Detailed Timeline'!$J5=""),"",IF(AND(11>='Detailed Timeline'!$I5,11<='Detailed Timeline'!$J5),"■","")) | O5: =IF(OR('Detailed Timeline'!$I5="",'Detailed Timeline'!$J5=""),"",IF(AND(12>='Detailed Timeline'!$I5,12<='Detailed Timeline'!$J5),"■","")) | P5: =IF(OR('Detailed Timeline'!$I5="",'Detailed Timeline'!$J5=""),"",IF(AND(13>='Detailed Timeline'!$I5,13<='Detailed Timeline'!$J5),"■","")) | Q5: =IF(OR('Detailed Timeline'!$I5="",'Detailed Timeline'!$J5=""),"",IF(AND(14>='Detailed Timeline'!$I5,14<='Detailed Timeline'!$J5),"■","")) | R5: =IF(OR('Detailed Timeline'!$I5="",'Detailed Timeline'!$J5=""),"",IF(AND(15>='Detailed Timeline'!$I5,15<='Detailed Timeline'!$J5),"■","")) | S5: =IF(OR('Detailed Timeline'!$I5="",'Detailed Timeline'!$J5=""),"",IF(AND(16>='Detailed Timeline'!$I5,16<='Detailed Timeline'!$J5),"■","")) | T5: =IF(OR('Detailed Timeline'!$I5="",'Detailed Timeline'!$J5=""),"",IF(AND(17>='Detailed Timeline'!$I5,17<='Detailed Timeline'!$J5),"■","")) | U5: =IF(OR('Detailed Timeline'!$I5="",'Detailed Timeline'!$J5=""),"",IF(AND(18>='Detailed Timeline'!$I5,18<='Detailed Timeline'!$J5),"■","")) | V5: =IF(OR('Detailed Timeline'!$I5="",'Detailed Timeline'!$J5=""),"",IF(AND(19>='Detailed Timeline'!$I5,19<='Detailed Timeline'!$J5),"■","")) | W5: =IF(OR('Detailed Timeline'!$I5="",'Detailed Timeline'!$J5=""),"",IF(AND(20>='Detailed Timeline'!$I5,20<='Detailed Timeline'!$J5),"■","")) | X5: =IF(OR('Detailed Timeline'!$I5="",'Detailed Timeline'!$J5=""),"",IF(AND(21>='Detailed Timeline'!$I5,21<='Detailed Timeline'!$J5),"■","")) | Y5: =IF(OR('Detailed Timeline'!$I5="",'Detailed Timeline'!$J5=""),"",IF(AND(22>='Detailed Timeline'!$I5,22<='Detailed Timeline'!$J5),"■","")) | Z5: =IF(OR('Detailed Timeline'!$I5="",'Detailed Timeline'!$J5=""),"",IF(AND(23>='Detailed Timeline'!$I5,23<='Detailed Timeline'!$J5),"■","")) | AA5: =IF(OR('Detailed Timeline'!$I5="",'Detailed Timeline'!$J5=""),"",IF(AND(24>='Detailed Timeline'!$I5,24<='Detailed Timeline'!$J5),"■","")) | AB5: =IF(OR('Detailed Timeline'!$I5="",'Detailed Timeline'!$J5=""),"",IF(AND(25>='Detailed Timeline'!$I5,25<='Detailed Timeline'!$J5),"■","")) | AC5: =IF(OR('Detailed Timeline'!$I5="",'Detailed Timeline'!$J5=""),"",IF(AND(26>='Detailed Timeline'!$I5,26<='Detailed Timeline'!$J5),"■",""))
A6: ='Detailed Timeline'!A7 | B6: ='Detailed Timeline'!B7 | C6: ='Detailed Timeline'!C7 | D6: =IF(OR('Detailed Timeline'!$I7="",'Detailed Timeline'!$J7=""),"",IF(AND(1>='Detailed Timeline'!$I7,1<='Detailed Timeline'!$J7),"■","")) | E6: =IF(OR('Detailed Timeline'!$I7="",'Detailed Timeline'!$J7=""),"",IF(AND(2>='Detailed Timeline'!$I7,2<='Detailed Timeline'!$J7),"■","")) | F6: =IF(OR('Detailed Timeline'!$I7="",'Detailed Timeline'!$J7=""),"",IF(AND(3>='Detailed Timeline'!$I7,3<='Detailed Timeline'!$J7),"■","")) | G6: =IF(OR('Detailed Timeline'!$I7="",'Detailed Timeline'!$J7=""),"",IF(AND(4>='Detailed Timeline'!$I7,4<='Detailed Timeline'!$J7),"■","")) | H6: =IF(OR('Detailed Timeline'!$I7="",'Detailed Timeline'!$J7=""),"",IF(AND(5>='Detailed Timeline'!$I7,5<='Detailed Timeline'!$J7),"■","")) | I6: =IF(OR('Detailed Timeline'!$I7="",'Detailed Timeline'!$J7=""),"",IF(AND(6>='Detailed Timeline'!$I7,6<='Detailed Timeline'!$J7),"■","")) | J6: =IF(OR('Detailed Timeline'!$I7="",'Detailed Timeline'!$J7=""),"",IF(AND(7>='Detailed Timeline'!$I7,7<='Detailed Timeline'!$J7),"■","")) | K6: =IF(OR('Detailed Timeline'!$I7="",'Detailed Timeline'!$J7=""),"",IF(AND(8>='Detailed Timeline'!$I7,8<='Detailed Timeline'!$J7),"■","")) | L6: =IF(OR('Detailed Timeline'!$I7="",'Detailed Timeline'!$J7=""),"",IF(AND(9>='Detailed Timeline'!$I7,9<='Detailed Timeline'!$J7),"■","")) | M6: =IF(OR('Detailed Timeline'!$I7="",'Detailed Timeline'!$J7=""),"",IF(AND(10>='Detailed Timeline'!$I7,10<='Detailed Timeline'!$J7),"■","")) | N6: =IF(OR('Detailed Timeline'!$I7="",'Detailed Timeline'!$J7=""),"",IF(AND(11>='Detailed Timeline'!$I7,11<='Detailed Timeline'!$J7),"■","")) | O6: =IF(OR('Detailed Timeline'!$I7="",'Detailed Timeline'!$J7=""),"",IF(AND(12>='Detailed Timeline'!$I7,12<='Detailed Timeline'!$J7),"■","")) | P6: =IF(OR('Detailed Timeline'!$I7="",'Detailed Timeline'!$J7=""),"",IF(AND(13>='Detailed Timeline'!$I7,13<='Detailed Timeline'!$J7),"■","")) | Q6: =IF(OR('Detailed Timeline'!$I7="",'Detailed Timeline'!$J7=""),"",IF(AND(14>='Detailed Timeline'!$I7,14<='Detailed Timeline'!$J7),"■","")) | R6: =IF(OR('Detailed Timeline'!$I7="",'Detailed Timeline'!$J7=""),"",IF(AND(15>='Detailed Timeline'!$I7,15<='Detailed Timeline'!$J7),"■","")) | S6: =IF(OR('Detailed Timeline'!$I7="",'Detailed Timeline'!$J7=""),"",IF(AND(16>='Detailed Timeline'!$I7,16<='Detailed Timeline'!$J7),"■","")) | T6: =IF(OR('Detailed Timeline'!$I7="",'Detailed Timeline'!$J7=""),"",IF(AND(17>='Detailed Timeline'!$I7,17<='Detailed Timeline'!$J7),"■","")) | U6: =IF(OR('Detailed Timeline'!$I7="",'Detailed Timeline'!$J7=""),"",IF(AND(18>='Detailed Timeline'!$I7,18<='Detailed Timeline'!$J7),"■","")) | V6: =IF(OR('Detailed Timeline'!$I7="",'Detailed Timeline'!$J7=""),"",IF(AND(19>='Detailed Timeline'!$I7,19<='Detailed Timeline'!$J7),"■","")) | W6: =IF(OR('Detailed Timeline'!$I7="",'Detailed Timeline'!$J7=""),"",IF(AND(20>='Detailed Timeline'!$I7,20<='Detailed Timeline'!$J7),"■","")) | X6: =IF(OR('Detailed Timeline'!$I7="",'Detailed Timeline'!$J7=""),"",IF(AND(21>='Detailed Timeline'!$I7,21<='Detailed Timeline'!$J7),"■","")) | Y6: =IF(OR('Detailed Timeline'!$I7="",'Detailed Timeline'!$J7=""),"",IF(AND(22>='Detailed Timeline'!$I7,22<='Detailed Timeline'!$J7),"■","")) | Z6: =IF(OR('Detailed Timeline'!$I7="",'Detailed Timeline'!$J7=""),"",IF(AND(23>='Detailed Timeline'!$I7,23<='Detailed Timeline'!$J7),"■","")) | AA6: =IF(OR('Detailed Timeline'!$I7="",'Detailed Timeline'!$J7=""),"",IF(AND(24>='Detailed Timeline'!$I7,24<='Detailed Timeline'!$J7),"■","")) | AB6: =IF(OR('Detailed Timeline'!$I7="",'Detailed Timeline'!$J7=""),"",IF(AND(25>='Detailed Timeline'!$I7,25<='Detailed Timeline'!$J7),"■","")) | AC6: =IF(OR('Detailed Timeline'!$I7="",'Detailed Timeline'!$J7=""),"",IF(AND(26>='Detailed Timeline'!$I7,26<='Detailed Timeline'!$J7),"■",""))
